<sdf version='1.7'>
  <world name='default'>
    <physics type='ode'>
      <ode>
        <solver>
          <type>quick</type>
          <iters>100</iters>
          <sor>1</sor>
          <use_dynamic_moi_rescaling>0</use_dynamic_moi_rescaling>
        </solver>
        <constraints>
          <cfm>0</cfm>
          <erp>0.9</erp>
          <contact_max_correcting_vel>0.1</contact_max_correcting_vel>
          <contact_surface_layer>0</contact_surface_layer>
        </constraints>
      </ode>
      <real_time_update_rate>-1</real_time_update_rate>
      <max_step_size>0.001</max_step_size>
      <real_time_factor>1</real_time_factor>
    </physics>
    <light name='sun' type='directional'>
      <cast_shadows>1</cast_shadows>
      <pose>0 0 10 0 -0 0</pose>
      <diffuse>0.8 0.8 0.8 1</diffuse>
      <specular>0.2 0.2 0.2 1</specular>
      <attenuation>
        <range>1000</range>
        <constant>0.9</constant>
        <linear>0.01</linear>
        <quadratic>0.001</quadratic>
      </attenuation>
      <direction>-0.5 0.1 -0.9</direction>
      <spot>
        <inner_angle>0</inner_angle>
        <outer_angle>0</outer_angle>
        <falloff>0</falloff>
      </spot>
    </light>
    <model name='ground_plane'>
      <static>1</static>
      <link name='link'>
        <collision name='collision'>
          <geometry>
            <plane>
              <normal>0 0 1</normal>
              <size>100 100</size>
            </plane>
          </geometry>
          <surface>
            <contact>
              <collide_bitmask>65535</collide_bitmask>
              <ode/>
            </contact>
            <friction>
              <ode>
                <mu>100</mu>
                <mu2>50</mu2>
              </ode>
              <torsional>
                <ode/>
              </torsional>
            </friction>
            <bounce/>
          </surface>
          <max_contacts>10</max_contacts>
        </collision>
        <visual name='visual'>
          <cast_shadows>0</cast_shadows>
          <geometry>
            <plane>
              <normal>0 0 1</normal>
              <size>100 100</size>
            </plane>
          </geometry>
          <material>
            <script>
              <uri>file://media/materials/scripts/gazebo.material</uri>
              <name>Gazebo/Grey</name>
            </script>
          </material>
        </visual>
        <self_collide>0</self_collide>
        <enable_wind>0</enable_wind>
        <kinematic>0</kinematic>
      </link>
    </model>
    <model name='iris'>
      <frame name='iris_demo::__model__' attached_to='iris_demo::iris::base_link'>
        <pose relative_to='__model__'>0 0 0 0 -0 0</pose>
      </frame>
      <frame name='iris_demo::iris::__model__' attached_to='iris_demo::iris::base_link'>
        <pose relative_to='iris_demo::__model__'>0 0 0.194923 0 -0 0</pose>
      </frame>
      <link name='iris_demo::iris::base_link'>
        <velocity_decay>
          <linear>0</linear>
          <angular>0</angular>
        </velocity_decay>
        <inertial>
          <pose>0 0 0 0 -0 0</pose>
          <mass>1.5</mass>
          <inertia>
            <ixx>0.008</ixx>
            <ixy>0</ixy>
            <ixz>0</ixz>
            <iyy>0.015</iyy>
            <iyz>0</iyz>
            <izz>0.017</izz>
          </inertia>
        </inertial>
        <collision name='base_link_collision'>
          <pose>0 0 -0.08 0 -0 0</pose>
          <geometry>
            <box>
              <size>0.47 0.47 0.23</size>
            </box>
          </geometry>
          <surface>
            <contact>
              <ode>
                <max_vel>100</max_vel>
                <min_depth>0.001</min_depth>
              </ode>
            </contact>
            <friction>
              <ode>
                <mu>100000</mu>
                <mu2>100000</mu2>
              </ode>
              <torsional>
                <ode/>
              </torsional>
            </friction>
            <bounce/>
          </surface>
          <max_contacts>10</max_contacts>
        </collision>
        <visual name='base_link_visual'>
          <geometry>
            <mesh>
              <uri>model://iris_with_standoffs/meshes/iris.dae</uri>
            </mesh>
          </geometry>
          <material>
            <script>
              <name>Gazebo/DarkGrey</name>
              <uri>__default__</uri>
            </script>
          </material>
        </visual>
        <visual name='front_left_leg_visual'>
          <pose>0.123 0.22 -0.11 0 -0 0</pose>
          <geometry>
            <cylinder>
              <radius>0.005</radius>
              <length>0.17</length>
            </cylinder>
          </geometry>
          <material>
            <script>
              <name>Gazebo/FlatBlack</name>
              <uri>file://media/materials/scripts/gazebo.material</uri>
            </script>
          </material>
        </visual>
        <visual name='front_right_leg_visual'>
          <pose>0.123 -0.22 -0.11 0 -0 0</pose>
          <geometry>
            <cylinder>
              <radius>0.005</radius>
              <length>0.17</length>
            </cylinder>
          </geometry>
          <material>
            <script>
              <name>Gazebo/FlatBlack</name>
              <uri>file://media/materials/scripts/gazebo.material</uri>
            </script>
          </material>
        </visual>
        <visual name='rear_left_leg_visual'>
          <pose>-0.14 0.21 -0.11 0 -0 0</pose>
          <geometry>
            <cylinder>
              <radius>0.005</radius>
              <length>0.17</length>
            </cylinder>
          </geometry>
          <material>
            <script>
              <name>Gazebo/FlatBlack</name>
              <uri>file://media/materials/scripts/gazebo.material</uri>
            </script>
          </material>
        </visual>
        <visual name='rear_right_leg_visual'>
          <pose>-0.14 -0.21 -0.11 0 -0 0</pose>
          <geometry>
            <cylinder>
              <radius>0.005</radius>
              <length>0.17</length>
            </cylinder>
          </geometry>
          <material>
            <script>
              <name>Gazebo/FlatBlack</name>
              <uri>file://media/materials/scripts/gazebo.material</uri>
            </script>
          </material>
        </visual>
        <pose relative_to='iris_demo::iris::__model__'>0 0 0 0 -0 0</pose>
        <self_collide>0</self_collide>
        <enable_wind>0</enable_wind>
        <kinematic>0</kinematic>
      </link>
      <link name='iris_demo::iris::iris/ground_truth/odometry_sensorgt_link'>
        <pose relative_to='iris_demo::iris::__model__'>0 0 0 0 -0 0</pose>
        <inertial>
          <pose>0 0 0 0 -0 0</pose>
          <mass>0.15</mass>
          <inertia>
            <ixx>0.0001</ixx>
            <ixy>0</ixy>
            <ixz>0</ixz>
            <iyy>0.0002</iyy>
            <iyz>0</iyz>
            <izz>0.0002</izz>
          </inertia>
        </inertial>
        <self_collide>0</self_collide>
        <enable_wind>0</enable_wind>
        <kinematic>0</kinematic>
      </link>
      <joint name='iris_demo::iris::iris/ground_truth/odometry_sensorgt_joint' type='revolute'>
        <child>iris_demo::iris::iris/ground_truth/odometry_sensorgt_link</child>
        <parent>iris_demo::iris::base_link</parent>
        <axis>
          <xyz expressed_in='iris_demo::iris::__model__'>0 0 1</xyz>
          <limit>
            <lower>0</lower>
            <upper>0</upper>
            <effort>0</effort>
            <velocity>0</velocity>
          </limit>
          <dynamics>
            <damping>1</damping>
            <spring_reference>0</spring_reference>
            <spring_stiffness>0</spring_stiffness>
          </dynamics>
        </axis>
        <physics>
          <ode>
            <implicit_spring_damper>1</implicit_spring_damper>
            <limit>
              <cfm>0</cfm>
              <erp>0.2</erp>
            </limit>
          </ode>
        </physics>
      </joint>
      <link name='iris_demo::iris::iris/imu_link'>
        <inertial>
          <pose>0 0 0 0 -0 0</pose>
          <mass>0.15</mass>
          <inertia>
            <ixx>1e-05</ixx>
            <ixy>0</ixy>
            <ixz>0</ixz>
            <iyy>2e-05</iyy>
            <iyz>0</iyz>
            <izz>2e-05</izz>
          </inertia>
        </inertial>
        <sensor name='imu_sensor' type='imu'>
          <pose>0 0 0 -3.14159 -0 0</pose>
          <always_on>1</always_on>
          <update_rate>1000</update_rate>
          <imu/>
        </sensor>
        <pose relative_to='iris_demo::iris::__model__'>0 0 0 0 -0 0</pose>
        <self_collide>0</self_collide>
        <enable_wind>0</enable_wind>
        <kinematic>0</kinematic>
      </link>
      <joint name='iris_demo::iris::iris/imu_joint' type='revolute'>
        <child>iris_demo::iris::iris/imu_link</child>
        <parent>iris_demo::iris::base_link</parent>
        <axis>
          <xyz expressed_in='iris_demo::iris::__model__'>0 0 1</xyz>
          <limit>
            <lower>0</lower>
            <upper>0</upper>
            <effort>0</effort>
            <velocity>0</velocity>
          </limit>
          <dynamics>
            <damping>1</damping>
            <spring_reference>0</spring_reference>
            <spring_stiffness>0</spring_stiffness>
          </dynamics>
        </axis>
        <physics>
          <ode>
            <implicit_spring_damper>1</implicit_spring_damper>
            <limit>
              <cfm>0</cfm>
              <erp>0.2</erp>
            </limit>
          </ode>
        </physics>
      </joint>
      <link name='iris_demo::iris::rotor_0'>
        <pose relative_to='iris_demo::iris::__model__'>0.13 -0.22 0.023 0 -0 0</pose>
        <inertial>
          <pose>0 0 0 0 -0 0</pose>
          <mass>0.025</mass>
          <inertia>
            <ixx>9.75e-06</ixx>
            <ixy>0</ixy>
            <ixz>0</ixz>
            <iyy>0.000166704</iyy>
            <iyz>0</iyz>
            <izz>0.000167604</izz>
          </inertia>
        </inertial>
        <collision name='rotor_0_collision'>
          <pose>0 0 0 0 -0 0</pose>
          <geometry>
            <cylinder>
              <length>0.005</length>
              <radius>0.1</radius>
            </cylinder>
          </geometry>
          <surface>
            <contact>
              <ode/>
            </contact>
            <friction>
              <ode/>
              <torsional>
                <ode/>
              </torsional>
            </friction>
            <bounce/>
          </surface>
          <max_contacts>10</max_contacts>
        </collision>
        <visual name='rotor_0_visual'>
          <pose>0 0 0 0 -0 0</pose>
          <geometry>
            <mesh>
              <scale>1 1 1</scale>
              <uri>model://iris_with_standoffs/meshes/iris_prop_ccw.dae</uri>
            </mesh>
          </geometry>
          <material>
            <script>
              <name>Gazebo/Blue</name>
              <uri>__default__</uri>
            </script>
          </material>
        </visual>
        <gravity>1</gravity>
        <velocity_decay/>
        <self_collide>0</self_collide>
        <enable_wind>0</enable_wind>
        <kinematic>0</kinematic>
      </link>
      <joint name='iris_demo::iris::rotor_0_joint' type='revolute'>
        <child>iris_demo::iris::rotor_0</child>
        <parent>iris_demo::iris::base_link</parent>
        <axis>
          <xyz expressed_in='iris_demo::iris::__model__'>0 0 1</xyz>
          <limit>
            <lower>-1e+16</lower>
            <upper>1e+16</upper>
          </limit>
          <dynamics>
            <damping>0.004</damping>
            <spring_reference>0</spring_reference>
            <spring_stiffness>0</spring_stiffness>
          </dynamics>
        </axis>
        <physics>
          <ode>
            <implicit_spring_damper>1</implicit_spring_damper>
            <limit>
              <cfm>0</cfm>
              <erp>0.2</erp>
            </limit>
          </ode>
        </physics>
      </joint>
      <link name='iris_demo::iris::rotor_1'>
        <pose relative_to='iris_demo::iris::__model__'>-0.13 0.2 0.023 0 -0 0</pose>
        <inertial>
          <pose>0 0 0 0 -0 0</pose>
          <mass>0.025</mass>
          <inertia>
            <ixx>9.75e-06</ixx>
            <ixy>0</ixy>
            <ixz>0</ixz>
            <iyy>0.000166704</iyy>
            <iyz>0</iyz>
            <izz>0.000167604</izz>
          </inertia>
        </inertial>
        <collision name='rotor_1_collision'>
          <pose>0 0 0 0 -0 0</pose>
          <geometry>
            <cylinder>
              <length>0.005</length>
              <radius>0.1</radius>
            </cylinder>
          </geometry>
          <surface>
            <contact>
              <ode/>
            </contact>
            <friction>
              <ode/>
              <torsional>
                <ode/>
              </torsional>
            </friction>
            <bounce/>
          </surface>
          <max_contacts>10</max_contacts>
        </collision>
        <visual name='rotor_1_visual'>
          <pose>0 0 0 0 -0 0</pose>
          <geometry>
            <mesh>
              <scale>1 1 1</scale>
              <uri>model://iris_with_standoffs/meshes/iris_prop_ccw.dae</uri>
            </mesh>
          </geometry>
          <material>
            <script>
              <name>Gazebo/DarkGrey</name>
              <uri>__default__</uri>
            </script>
          </material>
        </visual>
        <gravity>1</gravity>
        <velocity_decay/>
        <self_collide>0</self_collide>
        <enable_wind>0</enable_wind>
        <kinematic>0</kinematic>
      </link>
      <joint name='iris_demo::iris::rotor_1_joint' type='revolute'>
        <child>iris_demo::iris::rotor_1</child>
        <parent>iris_demo::iris::base_link</parent>
        <axis>
          <xyz expressed_in='iris_demo::iris::__model__'>0 0 1</xyz>
          <limit>
            <lower>-1e+16</lower>
            <upper>1e+16</upper>
          </limit>
          <dynamics>
            <damping>0.004</damping>
            <spring_reference>0</spring_reference>
            <spring_stiffness>0</spring_stiffness>
          </dynamics>
        </axis>
        <physics>
          <ode>
            <implicit_spring_damper>1</implicit_spring_damper>
            <limit>
              <cfm>0</cfm>
              <erp>0.2</erp>
            </limit>
          </ode>
        </physics>
      </joint>
      <link name='iris_demo::iris::rotor_2'>
        <pose relative_to='iris_demo::iris::__model__'>0.13 0.22 0.023 0 -0 0</pose>
        <inertial>
          <pose>0 0 0 0 -0 0</pose>
          <mass>0.025</mass>
          <inertia>
            <ixx>9.75e-06</ixx>
            <ixy>0</ixy>
            <ixz>0</ixz>
            <iyy>0.000166704</iyy>
            <iyz>0</iyz>
            <izz>0.000167604</izz>
          </inertia>
        </inertial>
        <collision name='rotor_2_collision'>
          <pose>0 0 0 0 -0 0</pose>
          <geometry>
            <cylinder>
              <length>0.005</length>
              <radius>0.1</radius>
            </cylinder>
          </geometry>
          <surface>
            <contact>
              <ode/>
            </contact>
            <friction>
              <ode/>
              <torsional>
                <ode/>
              </torsional>
            </friction>
            <bounce/>
          </surface>
          <max_contacts>10</max_contacts>
        </collision>
        <visual name='rotor_2_visual'>
          <pose>0 0 0 0 -0 0</pose>
          <geometry>
            <mesh>
              <scale>1 1 1</scale>
              <uri>model://iris_with_standoffs/meshes/iris_prop_cw.dae</uri>
            </mesh>
          </geometry>
          <material>
            <script>
              <name>Gazebo/Blue</name>
              <uri>__default__</uri>
            </script>
          </material>
        </visual>
        <gravity>1</gravity>
        <velocity_decay/>
        <self_collide>0</self_collide>
        <enable_wind>0</enable_wind>
        <kinematic>0</kinematic>
      </link>
      <joint name='iris_demo::iris::rotor_2_joint' type='revolute'>
        <child>iris_demo::iris::rotor_2</child>
        <parent>iris_demo::iris::base_link</parent>
        <axis>
          <xyz expressed_in='iris_demo::iris::__model__'>0 0 1</xyz>
          <limit>
            <lower>-1e+16</lower>
            <upper>1e+16</upper>
          </limit>
          <dynamics>
            <damping>0.004</damping>
            <spring_reference>0</spring_reference>
            <spring_stiffness>0</spring_stiffness>
          </dynamics>
        </axis>
        <physics>
          <ode>
            <implicit_spring_damper>1</implicit_spring_damper>
            <limit>
              <cfm>0</cfm>
              <erp>0.2</erp>
            </limit>
          </ode>
        </physics>
      </joint>
      <link name='iris_demo::iris::rotor_3'>
        <pose relative_to='iris_demo::iris::__model__'>-0.13 -0.2 0.023 0 -0 0</pose>
        <inertial>
          <pose>0 0 0 0 -0 0</pose>
          <mass>0.025</mass>
          <inertia>
            <ixx>9.75e-06</ixx>
            <ixy>0</ixy>
            <ixz>0</ixz>
            <iyy>0.000166704</iyy>
            <iyz>0</iyz>
            <izz>0.000167604</izz>
          </inertia>
        </inertial>
        <collision name='rotor_3_collision'>
          <pose>0 0 0 0 -0 0</pose>
          <geometry>
            <cylinder>
              <length>0.005</length>
              <radius>0.1</radius>
            </cylinder>
          </geometry>
          <surface>
            <contact>
              <ode/>
            </contact>
            <friction>
              <ode/>
              <torsional>
                <ode/>
              </torsional>
            </friction>
            <bounce/>
          </surface>
          <max_contacts>10</max_contacts>
        </collision>
        <visual name='rotor_3_visual'>
          <pose>0 0 0 0 -0 0</pose>
          <geometry>
            <mesh>
              <scale>1 1 1</scale>
              <uri>model://iris_with_standoffs/meshes/iris_prop_cw.dae</uri>
            </mesh>
          </geometry>
          <material>
            <script>
              <name>Gazebo/DarkGrey</name>
              <uri>__default__</uri>
            </script>
          </material>
        </visual>
        <gravity>1</gravity>
        <velocity_decay/>
        <self_collide>0</self_collide>
        <enable_wind>0</enable_wind>
        <kinematic>0</kinematic>
      </link>
      <joint name='iris_demo::iris::rotor_3_joint' type='revolute'>
        <child>iris_demo::iris::rotor_3</child>
        <parent>iris_demo::iris::base_link</parent>
        <axis>
          <xyz expressed_in='iris_demo::iris::__model__'>0 0 1</xyz>
          <limit>
            <lower>-1e+16</lower>
            <upper>1e+16</upper>
          </limit>
          <dynamics>
            <damping>0.004</damping>
            <spring_reference>0</spring_reference>
            <spring_stiffness>0</spring_stiffness>
          </dynamics>
        </axis>
        <physics>
          <ode>
            <implicit_spring_damper>1</implicit_spring_damper>
            <limit>
              <cfm>0</cfm>
              <erp>0.2</erp>
            </limit>
          </ode>
        </physics>
      </joint>
      <static>0</static>
      <frame name='iris_demo::gimbal_small_2d::__model__' attached_to='iris_demo::gimbal_small_2d::base_link'>
        <pose relative_to='iris_demo::__model__'>0 -0.01 0.07 1.57 -0 1.57</pose>
      </frame>
      <link name='iris_demo::gimbal_small_2d::base_link'>
        <inertial>
          <mass>0.2</mass>
          <inertia>
            <ixx>0.0001</ixx>
            <ixy>0</ixy>
            <ixz>0</ixz>
            <iyy>0.0001</iyy>
            <iyz>0</iyz>
            <izz>0.0001</izz>
          </inertia>
          <pose>0 0 0 0 -0 0</pose>
        </inertial>
        <visual name='base_main_viz'>
          <geometry>
            <mesh>
              <scale>0.001 0.001 0.001</scale>
              <uri>model://gimbal_small_2d/meshes/base_main.dae</uri>
            </mesh>
          </geometry>
          <material>
            <script>
              <uri>file://media/materials/scripts/gazebo.material</uri>
              <name>Gazebo/FlatBlack</name>
            </script>
          </material>
        </visual>
        <visual name='base_arm_viz'>
          <geometry>
            <mesh>
              <scale>0.001 0.001 0.001</scale>
              <uri>model://gimbal_small_2d/meshes/base_arm.dae</uri>
            </mesh>
          </geometry>
          <material>
            <script>
              <uri>file://media/materials/scripts/gazebo.material</uri>
              <name>Gazebo/FlatBlack</name>
            </script>
          </material>
        </visual>
        <collision name='base_col'>
          <pose>0.01 0.075 -0.025 0 -0 0</pose>
          <geometry>
            <box>
              <size>0.1 0.05 0.15</size>
            </box>
          </geometry>
          <surface>
            <friction>
              <ode>
                <mu>1</mu>
                <mu2>1</mu2>
                <fdir1>0 0 0</fdir1>
                <slip1>0</slip1>
                <slip2>0</slip2>
              </ode>
              <torsional>
                <ode/>
              </torsional>
            </friction>
            <contact>
              <ode/>
            </contact>
            <bounce/>
          </surface>
          <max_contacts>10</max_contacts>
        </collision>
        <pose relative_to='iris_demo::gimbal_small_2d::__model__'>0 0 0 0 -0 0</pose>
        <self_collide>0</self_collide>
        <enable_wind>0</enable_wind>
        <kinematic>0</kinematic>
      </link>
      <link name='iris_demo::gimbal_small_2d::tilt_link'>
        <inertial>
          <mass>0.01</mass>
          <inertia>
            <ixx>1e-05</ixx>
            <ixy>0</ixy>
            <ixz>0</ixz>
            <iyy>1e-05</iyy>
            <iyz>0</iyz>
            <izz>1e-05</izz>
          </inertia>
          <pose>0 0 0 0 -0 0</pose>
        </inertial>
        <visual name='tilt_viz'>
          <pose>0 0 -0.005 0 -0 0</pose>
          <geometry>
            <mesh>
              <scale>0.001 0.001 0.001</scale>
              <uri>model://gimbal_small_2d/meshes/tilt.dae</uri>
            </mesh>
          </geometry>
          <material>
            <script>
              <uri>file://media/materials/scripts/gazebo.material</uri>
              <name>Gazebo/Grey</name>
            </script>
          </material>
        </visual>
        <collision name='tilt_col'>
          <pose>0 0 -0.005 0 -0 0</pose>
          <geometry>
            <mesh>
              <scale>0.001 0.001 0.001</scale>
              <uri>model://gimbal_small_2d/meshes/tilt.dae</uri>
            </mesh>
          </geometry>
          <max_contacts>10</max_contacts>
          <surface>
            <contact>
              <ode/>
            </contact>
            <bounce/>
            <friction>
              <torsional>
                <ode/>
              </torsional>
              <ode/>
            </friction>
          </surface>
        </collision>
        <visual name='camera_viz'>
          <pose>0 0 0.02 0 -0 0</pose>
          <geometry>
            <cylinder>
              <radius>0.025</radius>
              <length>0.05</length>
            </cylinder>
          </geometry>
          <material>
            <script>
              <uri>file://media/materials/scripts/gazebo.material</uri>
              <name>Gazebo/Grey</name>
            </script>
          </material>
        </visual>
        <collision name='camera_col'>
          <pose>0 0 0.02 0 -0 0</pose>
          <geometry>
            <cylinder>
              <radius>0.025</radius>
              <length>0.05</length>
            </cylinder>
          </geometry>
          <max_contacts>10</max_contacts>
          <surface>
            <contact>
              <ode/>
            </contact>
            <bounce/>
            <friction>
              <torsional>
                <ode/>
              </torsional>
              <ode/>
            </friction>
          </surface>
        </collision>
        <sensor name='camera' type='camera'>
          <pose>0 0 0 -1.57 -1.57 0</pose>
          <camera>
            <horizontal_fov>2</horizontal_fov>
            <image>
              <width>640</width>
              <height>480</height>
            </image>
            <clip>
              <near>0.05</near>
              <far>15000</far>
            </clip>
          </camera>
          <always_on>1</always_on>
          <update_rate>10</update_rate>
          <visualize>1</visualize>
        </sensor>
        <pose relative_to='iris_demo::gimbal_small_2d::__model__'>0 0 0 0 -0 0</pose>
        <self_collide>0</self_collide>
        <enable_wind>0</enable_wind>
        <kinematic>0</kinematic>
      </link>
      <joint name='iris_demo::gimbal_small_2d::tilt_joint' type='revolute'>
        <parent>iris_demo::gimbal_small_2d::base_link</parent>
        <child>iris_demo::gimbal_small_2d::tilt_link</child>
        <physics>
          <ode>
            <implicit_spring_damper>1</implicit_spring_damper>
            <limit>
              <cfm>0</cfm>
              <erp>0.2</erp>
            </limit>
          </ode>
        </physics>
        <axis>
          <xyz expressed_in='iris_demo::gimbal_small_2d::__model__'>1 0 0</xyz>
          <dynamics>
            <damping>0.5</damping>
            <spring_reference>0</spring_reference>
            <spring_stiffness>0</spring_stiffness>
          </dynamics>
          <limit>
            <lower>-0.1</lower>
            <upper>3.14159</upper>
            <effort>10</effort>
            <velocity>-1</velocity>
          </limit>
        </axis>
        <pose>0 0 0.02 0 -0 0</pose>
      </joint>
      <plugin name='gimbal_small_2d' filename='libGimbalSmall2dPlugin.so'>
        <joint>iris_demo::gimbal_small_2d::tilt_joint</joint>
      </plugin>
      <joint name='iris_demo::iris_gimbal_mount' type='revolute'>
        <parent>iris_demo::iris::base_link</parent>
        <child>iris_demo::gimbal_small_2d::base_link</child>
        <axis>
          <limit>
            <lower>0</lower>
            <upper>0</upper>
          </limit>
          <xyz expressed_in='iris_demo::__model__'>0 0 1</xyz>
          <dynamics>
            <spring_reference>0</spring_reference>
            <spring_stiffness>0</spring_stiffness>
          </dynamics>
        </axis>
      </joint>
      <plugin name='rotor_0_blade_1' filename='libLiftDragPlugin.so'>
        <a0>0.1</a0>
        <alpha_stall>1.4</alpha_stall>
        <cla>0.2500</cla>
        <cda>0.10</cda>
        <cma>0.00</cma>
        <cla_stall>-0.025</cla_stall>
        <cda_stall>0.0</cda_stall>
        <cma_stall>0.0</cma_stall>
        <area>0.2</area>
        <air_density>1.2041</air_density>
        <cp>0.084 0 0</cp>
        <forward>0 1 0</forward>
        <upward>0 0 1</upward>
        <link_name>iris_demo::iris::rotor_0</link_name>
      </plugin>
      <plugin name='rotor_0_blade_2' filename='libLiftDragPlugin.so'>
        <a0>0.1</a0>
        <alpha_stall>1.4</alpha_stall>
        <cla>0.2500</cla>
        <cda>0.10</cda>
        <cma>0.00</cma>
        <cla_stall>-0.025</cla_stall>
        <cda_stall>0.0</cda_stall>
        <cma_stall>0.0</cma_stall>
        <area>0.2</area>
        <air_density>1.2041</air_density>
        <cp>-0.084 0 0</cp>
        <forward>0 -1 0</forward>
        <upward>0 0 1</upward>
        <link_name>iris_demo::iris::rotor_0</link_name>
      </plugin>
      <plugin name='rotor_1_blade_1' filename='libLiftDragPlugin.so'>
        <a0>0.1</a0>
        <alpha_stall>1.4</alpha_stall>
        <cla>0.2500</cla>
        <cda>0.10</cda>
        <cma>0.00</cma>
        <cla_stall>-0.025</cla_stall>
        <cda_stall>0.0</cda_stall>
        <cma_stall>0.0</cma_stall>
        <area>0.2</area>
        <air_density>1.2041</air_density>
        <cp>0.084 0 0</cp>
        <forward>0 1 0</forward>
        <upward>0 0 1</upward>
        <link_name>iris_demo::iris::rotor_1</link_name>
      </plugin>
      <plugin name='rotor_1_blade_2' filename='libLiftDragPlugin.so'>
        <a0>0.1</a0>
        <alpha_stall>1.4</alpha_stall>
        <cla>0.2500</cla>
        <cda>0.10</cda>
        <cma>0.00</cma>
        <cla_stall>-0.025</cla_stall>
        <cda_stall>0.0</cda_stall>
        <cma_stall>0.0</cma_stall>
        <area>0.2</area>
        <air_density>1.2041</air_density>
        <cp>-0.084 0 0</cp>
        <forward>0 -1 0</forward>
        <upward>0 0 1</upward>
        <link_name>iris_demo::iris::rotor_1</link_name>
      </plugin>
      <plugin name='rotor_2_blade_1' filename='libLiftDragPlugin.so'>
        <a0>0.1</a0>
        <alpha_stall>1.4</alpha_stall>
        <cla>0.2500</cla>
        <cda>0.10</cda>
        <cma>0.00</cma>
        <cla_stall>-0.025</cla_stall>
        <cda_stall>0.0</cda_stall>
        <cma_stall>0.0</cma_stall>
        <area>0.2</area>
        <air_density>1.2041</air_density>
        <cp>0.084 0 0</cp>
        <forward>0 -1 0</forward>
        <upward>0 0 1</upward>
        <link_name>iris_demo::iris::rotor_2</link_name>
      </plugin>
      <plugin name='rotor_2_blade_2' filename='libLiftDragPlugin.so'>
        <a0>0.1</a0>
        <alpha_stall>1.4</alpha_stall>
        <cla>0.2500</cla>
        <cda>0.10</cda>
        <cma>0.00</cma>
        <cla_stall>-0.025</cla_stall>
        <cda_stall>0.0</cda_stall>
        <cma_stall>0.0</cma_stall>
        <area>0.2</area>
        <air_density>1.2041</air_density>
        <cp>-0.084 0 0</cp>
        <forward>0 1 0</forward>
        <upward>0 0 1</upward>
        <link_name>iris_demo::iris::rotor_2</link_name>
      </plugin>
      <plugin name='rotor_3_blade_1' filename='libLiftDragPlugin.so'>
        <a0>0.1</a0>
        <alpha_stall>1.4</alpha_stall>
        <cla>0.2500</cla>
        <cda>0.10</cda>
        <cma>0.00</cma>
        <cla_stall>-0.025</cla_stall>
        <cda_stall>0.0</cda_stall>
        <cma_stall>0.0</cma_stall>
        <area>0.2</area>
        <air_density>1.2041</air_density>
        <cp>0.084 0 0</cp>
        <forward>0 -1 0</forward>
        <upward>0 0 1</upward>
        <link_name>iris_demo::iris::rotor_3</link_name>
      </plugin>
      <plugin name='rotor_3_blade_2' filename='libLiftDragPlugin.so'>
        <a0>0.1</a0>
        <alpha_stall>1.4</alpha_stall>
        <cla>0.2500</cla>
        <cda>0.10</cda>
        <cma>0.00</cma>
        <cla_stall>-0.025</cla_stall>
        <cda_stall>0.0</cda_stall>
        <cma_stall>0.0</cma_stall>
        <area>0.2</area>
        <air_density>1.2041</air_density>
        <cp>-0.084 0 0</cp>
        <forward>0 1 0</forward>
        <upward>0 0 1</upward>
        <link_name>iris_demo::iris::rotor_3</link_name>
      </plugin>
      <plugin name='arducopter_plugin' filename='libArduCopterPlugin.so'>
        <imuName>iris_demo::iris::iris/imu_link::imu_sensor</imuName>
        <connectionTimeoutMaxCount>5</connectionTimeoutMaxCount>
        <rotor id='0'>
          <vel_p_gain>0.01</vel_p_gain>
          <vel_i_gain>0</vel_i_gain>
          <vel_d_gain>0</vel_d_gain>
          <vel_i_max>0</vel_i_max>
          <vel_i_min>0</vel_i_min>
          <vel_cmd_max>2.0</vel_cmd_max>
          <vel_cmd_min>-2.0</vel_cmd_min>
          <jointName>iris_demo::iris::rotor_0_joint</jointName>
          <turningDirection>ccw</turningDirection>
          <rotorVelocitySlowdownSim>1</rotorVelocitySlowdownSim>
        </rotor>
        <rotor id='1'>
          <vel_p_gain>0.01</vel_p_gain>
          <vel_i_gain>0</vel_i_gain>
          <vel_d_gain>0</vel_d_gain>
          <vel_i_max>0</vel_i_max>
          <vel_i_min>0</vel_i_min>
          <vel_cmd_max>2.0</vel_cmd_max>
          <vel_cmd_min>-2.0</vel_cmd_min>
          <jointName>iris_demo::iris::rotor_1_joint</jointName>
          <turningDirection>ccw</turningDirection>
          <rotorVelocitySlowdownSim>1</rotorVelocitySlowdownSim>
        </rotor>
        <rotor id='2'>
          <vel_p_gain>0.01</vel_p_gain>
          <vel_i_gain>0</vel_i_gain>
          <vel_d_gain>0</vel_d_gain>
          <vel_i_max>0</vel_i_max>
          <vel_i_min>0</vel_i_min>
          <vel_cmd_max>2.0</vel_cmd_max>
          <vel_cmd_min>-2.0</vel_cmd_min>
          <jointName>iris_demo::iris::rotor_2_joint</jointName>
          <turningDirection>cw</turningDirection>
          <rotorVelocitySlowdownSim>1</rotorVelocitySlowdownSim>
        </rotor>
        <rotor id='3'>
          <vel_p_gain>0.01</vel_p_gain>
          <vel_i_gain>0</vel_i_gain>
          <vel_d_gain>0</vel_d_gain>
          <vel_i_max>0</vel_i_max>
          <vel_i_min>0</vel_i_min>
          <vel_cmd_max>2.0</vel_cmd_max>
          <vel_cmd_min>-2.0</vel_cmd_min>
          <jointName>iris_demo::iris::rotor_3_joint</jointName>
          <turningDirection>cw</turningDirection>
          <rotorVelocitySlowdownSim>1</rotorVelocitySlowdownSim>
        </rotor>
      </plugin>
      <link name='camera'>
        <pose>0 -0.01 0.07 1.57 -0 1.57</pose>
        <inertial>
          <pose>0 0 0 0 -0 0</pose>
          <mass>0.1</mass>
          <inertia>
            <ixx>0.001</ixx>
            <ixy>0</ixy>
            <ixz>0</ixz>
            <iyy>0.001</iyy>
            <iyz>0</iyz>
            <izz>0.001</izz>
          </inertia>
        </inertial>
        <visual name='visual'>
          <pose>0 0 0 0 -0 0</pose>
          <geometry>
            <cylinder>
              <radius>0.025</radius>
              <length>0.025</length>
            </cylinder>
          </geometry>
          <material>
            <script>
              <uri>file://media/materials/scripts/gazebo.material</uri>
              <name>Gazebo/Grey</name>
            </script>
          </material>
        </visual>
        <sensor name='camera' type='camera'>
          <pose>0 0 0 -1.57 -1.57 0</pose>
          <camera>
            <horizontal_fov>1.0472</horizontal_fov>
            <image>
              <width>640</width>
              <height>480</height>
            </image>
            <clip>
              <near>0.05</near>
              <far>1000</far>
            </clip>
          </camera>
          <always_on>1</always_on>
          <update_rate>10</update_rate>
          <visualize>1</visualize>
          <plugin name='camera_controller' filename='libgazebo_ros_camera.so'>
            <alwaysOn>1</alwaysOn>
            <updateRate>0.0</updateRate>
            <cameraName>webcam</cameraName>
            <imageTopicName>image_raw</imageTopicName>
            <cameraInfoTopicName>camera_info</cameraInfoTopicName>
            <frameName>camera_link</frameName>
            <hackBaseline>0.07</hackBaseline>
            <distortionK1>0.0</distortionK1>
            <distortionK2>0.0</distortionK2>
            <distortionK3>0.0</distortionK3>
            <distortionT1>0.0</distortionT1>
            <distortionT2>0.0</distortionT2>
          </plugin>
        </sensor>
        <self_collide>0</self_collide>
        <enable_wind>0</enable_wind>
        <kinematic>0</kinematic>
      </link>
      <joint name='base_camera_joint' type='revolute'>
        <pose>0 0 0 0 -0 0</pose>
        <parent>iris::iris_demo::gimbal_small_2d::tilt_link</parent>
        <child>camera</child>
        <axis>
          <limit>
            <lower>0</lower>
            <upper>0</upper>
          </limit>
          <xyz expressed_in='__model__'>0 0 1</xyz>
          <dynamics>
            <spring_reference>0</spring_reference>
            <spring_stiffness>0</spring_stiffness>
          </dynamics>
        </axis>
      </joint>
    </model>
    <model name='irlock_beacon_01'>
      <pose>1 -1 0.005 0 -0 0</pose>
      <link name='link'>
        <inertial>
          <pose>0 0 0 0 -0 0</pose>
          <mass>3</mass>
          <inertia>
            <ixx>0.019</ixx>
            <ixy>0</ixy>
            <ixz>0</ixz>
            <iyy>0.01</iyy>
            <iyz>0</iyz>
            <izz>0.01</izz>
          </inertia>
        </inertial>
        <collision name='collision'>
          <geometry>
            <box>
              <size>1 1 0.02</size>
            </box>
          </geometry>
          <surface>
            <friction>
              <ode>
                <mu>1</mu>
                <mu2>1</mu2>
                <fdir1>1 0 0</fdir1>
              </ode>
              <torsional>
                <ode/>
              </torsional>
            </friction>
            <contact>
              <ode>
                <kp>1e+12</kp>
                <kd>1</kd>
                <max_vel>10</max_vel>
                <min_depth>0.003</min_depth>
              </ode>
            </contact>
            <bounce/>
          </surface>
          <max_contacts>10</max_contacts>
        </collision>
        <visual name='visual2'>
          <geometry>
            <box>
              <size>1 1 0.018</size>
            </box>
          </geometry>
          <material>
            <script>
              <name>Gazebo/Green</name>
              <uri>__default__</uri>
            </script>
          </material>
        </visual>
        <visual name='visual'>
          <geometry>
            <box>
              <size>0.1 0.1 0.02</size>
            </box>
          </geometry>
          <material>
            <script>
              <name>Gazebo/Red</name>
              <uri>__default__</uri>
            </script>
          </material>
        </visual>
        <self_collide>0</self_collide>
        <enable_wind>0</enable_wind>
        <kinematic>0</kinematic>
      </link>
    </model>
    <gravity>0 0 -9.8</gravity>
    <magnetic_field>6e-06 2.3e-05 -4.2e-05</magnetic_field>
    <atmosphere type='adiabatic'/>
    <scene>
      <ambient>0.4 0.4 0.4 1</ambient>
      <background>0.7 0.7 0.7 1</background>
      <shadows>1</shadows>
    </scene>
    <wind/>
    <spherical_coordinates>
      <surface_model>EARTH_WGS84</surface_model>
      <latitude_deg>0</latitude_deg>
      <longitude_deg>0</longitude_deg>
      <elevation>0</elevation>
      <heading_deg>0</heading_deg>
    </spherical_coordinates>
    <state world_name='default'>
      <sim_time>6379 341000000</sim_time>
      <real_time>27 73948304</real_time>
      <wall_time>1696443488 44209136</wall_time>
      <iterations>14718</iterations>
      <model name='ground_plane'>
        <pose>0 0 0 0 -0 0</pose>
        <scale>1 1 1</scale>
        <link name='link'>
          <pose>0 0 0 0 -0 0</pose>
          <velocity>0 0 0 0 -0 0</velocity>
          <acceleration>0 0 0 0 -0 0</acceleration>
          <wrench>0 0 0 0 -0 0</wrench>
        </link>
      </model>
      <model name='iris'>
        <pose>-9.84549 10.0001 0.017739 6e-06 0.003701 -0.000207</pose>
        <scale>1 1 1</scale>
        <link name='camera'>
          <pose>-9.82516 9.99004 0.10768 -3.13824 -2e-06 1.56979</pose>
          <velocity>0.000197 -4e-05 9.7e-05 -0.001577 0.000169 7.3e-05</velocity>
          <acceleration>0.000726 -0.040742 -0.011313 -0.907323 0.000611 0.143312</acceleration>
          <wrench>7.3e-05 -0.004074 -0.001131 0 -0 0</wrench>
        </link>
        <link name='iris_demo::gimbal_small_2d::base_link'>
          <pose>-9.84523 9.99005 0.087738 1.5737 -3e-06 1.56979</pose>
          <velocity>0.000194 -7.4e-05 0.000102 0.000341 0.000152 0.000481</velocity>
          <acceleration>0.002535 -0.140603 -0.0064 0.677731 -0.021466 0.955994</acceleration>
          <wrench>0.000507 -0.028121 -0.00128 0 -0 0</wrench>
        </link>
        <link name='iris_demo::gimbal_small_2d::tilt_link'>
          <pose>-9.82517 9.99004 0.10768 -3.13824 -3e-06 1.56979</pose>
          <velocity>0.000197 -4.3e-05 9.9e-05 0.000227 0.000156 0.000448</velocity>
          <acceleration>0.002017 -0.051468 -0.006671 0.324102 -0.022551 0.897652</acceleration>
          <wrench>2e-05 -0.000515 -6.7e-05 0 -0 0</wrench>
        </link>
        <link name='iris_demo::iris::base_link'>
          <pose>-9.84477 10.0001 0.21266 6e-06 0.003701 -0.000207</pose>
          <velocity>0.000213 -0.000109 0.000106 0.000524 0.000164 4e-05</velocity>
          <acceleration>-0.00143 -0.209963 0.000446 1.04029 0.002808 0.071838</acceleration>
          <wrench>-0.002145 -0.314944 0.000668 0 -0 0</wrench>
        </link>
        <link name='iris_demo::iris::iris/ground_truth/odometry_sensorgt_link'>
          <pose>-9.84477 10.0001 0.21266 6e-06 0.0037 -0.000207</pose>
          <velocity>0.000213 -0.000117 0.000106 0.000349 0.000152 -7.3e-05</velocity>
          <acceleration>-0.000195 -0.226693 0.000401 0.694476 -0.021295 -0.150769</acceleration>
          <wrench>-2.9e-05 -0.034004 6e-05 0 -0 0</wrench>
        </link>
        <link name='iris_demo::iris::iris/imu_link'>
          <pose>-9.84477 10.0001 0.21266 6e-06 0.0037 -0.000207</pose>
          <velocity>0.000213 -0.000117 0.000106 0.000349 0.000152 -7.3e-05</velocity>
          <acceleration>-0.000195 -0.226209 0.000399 0.694096 -0.021291 -0.150856</acceleration>
          <wrench>-2.9e-05 -0.033931 6e-05 0 -0 0</wrench>
        </link>
        <link name='iris_demo::iris::rotor_0'>
          <pose>-9.71473 9.78003 0.235178 0.003391 -0.001482 1.98096</pose>
          <velocity>0.000218 -0.000124 9e-06 0.000349 0.000233 5e-06</velocity>
          <acceleration>-5.4e-05 -0.241009 -0.149413 2.45662 1.33204 -3.14111</acceleration>
          <wrench>-1e-06 -0.006025 -0.003735 0 -0 0</wrench>
        </link>
        <link name='iris_demo::iris::rotor_1'>
          <pose>-9.97464 10.2001 0.236142 -0.000544 0.00366 -0.149346</pose>
          <velocity>0.000216 -0.000126 0.000195 0.000347 0.000154 3e-06</velocity>
          <acceleration>-0.00123 -0.24214 0.135259 0.71482 -0.118624 -0.004665</acceleration>
          <wrench>-3.1e-05 -0.006053 0.003381 0 -0 0</wrench>
        </link>
        <link name='iris_demo::iris::rotor_2'>
          <pose>-9.71464 10.22 0.23518 -0.002847 0.002363 -0.879856</pose>
          <velocity>0.000216 -0.000124 0.000162 0.000345 0.000233 5e-06</velocity>
          <acceleration>-0.00158 -0.24048 0.154013 -0.812117 1.17139 0.000994</acceleration>
          <wrench>-4e-05 -0.006012 0.00385 0 -0 0</wrench>
        </link>
        <link name='iris_demo::iris::rotor_3'>
          <pose>-9.97472 9.80008 0.23614 -0.003524 -0.001128 -1.88227</pose>
          <velocity>0.000218 -0.000125 5.7e-05 0.000342 8.4e-05 7e-06</velocity>
          <acceleration>-2.8e-05 -0.241846 -0.138309 2.50469 -0.883203 -3.14124</acceleration>
          <wrench>-1e-06 -0.006046 -0.003458 0 -0 0</wrench>
        </link>
      </model>
      <model name='irlock_beacon_01'>
        <pose>0.20927 0.017657 0.008499 -0 -0.002998 -0.002981</pose>
        <scale>1 1 1</scale>
        <link name='link'>
          <pose>0.20927 0.017657 0.008499 -0 -0.002998 -0.002981</pose>
          <velocity>0 0 0 0 -0 0</velocity>
          <acceleration>1.7e-05 0.005549 -0 -0.013375 4e-06 0.010046</acceleration>
          <wrench>5e-05 0.016646 -0 0 -0 0</wrench>
        </link>
      </model>
      <model name='irlock_beacon_01_clone'>
        <pose>10.0172 -0.019004 0.007456 0 0.000912 0</pose>
        <scale>1 1 1</scale>
        <link name='link'>
          <pose>10.0172 -0.019004 0.007456 0 0.000912 0</pose>
          <velocity>0 0 0 0 -0 0</velocity>
          <acceleration>-0 0.005546 -0 -0.013372 -0 -0.010654</acceleration>
          <wrench>-0 0.016639 -0 0 -0 0</wrench>
        </link>
      </model>
      <model name='irlock_beacon_01_clone_0'>
        <pose>-9.84563 10.0009 0.008496 0 0.002993 -0.00214</pose>
        <scale>1 1 1</scale>
        <link name='link'>
          <pose>-9.84563 10.0009 0.008496 0 0.002993 -0.00214</pose>
          <velocity>0.000166 -7e-06 0.000129 0.000195 0.000246 4.1e-05</velocity>
          <acceleration>0.165999 -0.006757 0.129389 0.194892 0.246568 0.041251</acceleration>
          <wrench>0.497996 -0.020271 0.388168 0 -0 0</wrench>
        </link>
      </model>
      <model name='irlock_beacon_01_clone_1'>
        <pose>-9.97256 -10.0375 0.008498 0 0.002996 -0.001033</pose>
        <scale>1 1 1</scale>
        <link name='link'>
          <pose>-9.97256 -10.0375 0.008498 0 0.002996 -0.001033</pose>
          <velocity>0 0 0 0 -0 0</velocity>
          <acceleration>6e-06 0.005549 -0 -0.013375 1e-06 -0.010047</acceleration>
          <wrench>1.7e-05 0.016647 -0 0 -0 0</wrench>
        </link>
      </model>
      <model name='irlock_beacon_01_clone_2'>
        <pose>0.001114 -9.99977 0.008493 0 0.002986 -0.001256</pose>
        <scale>1 1 1</scale>
        <link name='link'>
          <pose>0.001114 -9.99977 0.008493 0 0.002986 -0.001256</pose>
          <velocity>0 0 0 0 -0 0</velocity>
          <acceleration>-7e-06 -0.005549 -0 0.013375 -2e-06 0.010049</acceleration>
          <wrench>-2.1e-05 -0.016647 -0 0 -0 0</wrench>
        </link>
      </model>
      <model name='irlock_beacon_01_clone_3'>
        <pose>-9.97259 0.037094 0.008493 -0 0.002986 -0.001185</pose>
        <scale>1 1 1</scale>
        <link name='link'>
          <pose>-9.97259 0.037094 0.008493 -0 0.002986 -0.001185</pose>
          <velocity>0 0 0 0 -0 0</velocity>
          <acceleration>7e-06 0.005549 -0 -0.013375 2e-06 -0.010049</acceleration>
          <wrench>2e-05 0.016647 -0 0 -0 0</wrench>
        </link>
      </model>
      <model name='irlock_beacon_01_clone_clone'>
        <pose>9.99538 9.96211 0.008495 -0 0.002991 0.01511</pose>
        <scale>1 1 1</scale>
        <link name='link'>
          <pose>9.99538 9.96211 0.008495 -0 0.002991 0.01511</pose>
          <velocity>0 0 0 0 -0 0</velocity>
          <acceleration>-8.4e-05 0.005548 -0 -0.013375 -2e-05 -0.010048</acceleration>
          <wrench>-0.000252 0.016645 -0 0 -0 0</wrench>
        </link>
      </model>
      <model name='irlock_beacon_01_clone_clone_0'>
        <pose>0.086956 9.98542 0.008499 -0 0.002998 0.002845</pose>
        <scale>1 1 1</scale>
        <link name='link'>
          <pose>0.086956 9.98542 0.008499 -0 0.002998 0.002845</pose>
          <velocity>0 0 0 0 -0 0</velocity>
          <acceleration>1.6e-05 -0.005549 -0 0.013375 4e-06 0.010046</acceleration>
          <wrench>4.7e-05 -0.016647 -0 0 -0 0</wrench>
        </link>
      </model>
      <model name='irlock_beacon_01_clone_clone_1'>
        <pose>9.97725 -9.96773 0.007456 0 0.000912 0</pose>
        <scale>1 1 1</scale>
        <link name='link'>
          <pose>9.97725 -9.96773 0.007456 0 0.000912 0</pose>
          <velocity>0 0 0 0 -0 0</velocity>
          <acceleration>-0 0.005546 -0 -0.013372 -0 -0.010654</acceleration>
          <wrench>-0 0.016639 -0 0 -0 0</wrench>
        </link>
      </model>
      <light name='sun'>
        <pose>0 0 10 0 -0 0</pose>
      </light>
    </state>
    <gui fullscreen='0'>
      <camera name='user_camera'>
        <pose>-3.6337 3.50791 77.005 3.14159 1.57079 3.14159</pose>
        <view_controller>orbit</view_controller>
        <projection_type>perspective</projection_type>
      </camera>
    </gui>
    <model name='irlock_beacon_01_clone'>
      <pose>9.51075 -0.052867 0.008497 -0 0.002996 0.00027</pose>
      <link name='link'>
        <inertial>
          <pose>0 0 0 0 -0 0</pose>
          <mass>3</mass>
          <inertia>
            <ixx>0.019</ixx>
            <ixy>0</ixy>
            <ixz>0</ixz>
            <iyy>0.01</iyy>
            <iyz>0</iyz>
            <izz>0.01</izz>
          </inertia>
        </inertial>
        <collision name='collision'>
          <geometry>
            <box>
              <size>1 1 0.02</size>
            </box>
          </geometry>
          <surface>
            <friction>
              <ode>
                <mu>1</mu>
                <mu2>1</mu2>
                <fdir1>1 0 0</fdir1>
              </ode>
              <torsional>
                <ode/>
              </torsional>
            </friction>
            <contact>
              <ode>
                <kp>1e+12</kp>
                <kd>1</kd>
                <max_vel>10</max_vel>
                <min_depth>0.003</min_depth>
              </ode>
            </contact>
            <bounce/>
          </surface>
          <max_contacts>10</max_contacts>
        </collision>
        <visual name='visual2'>
          <geometry>
            <box>
              <size>1 1 0.018</size>
            </box>
          </geometry>
          <material>
            <script>
              <name>Gazebo/Green</name>
              <uri>__default__</uri>
            </script>
          </material>
        </visual>
        <visual name='visual'>
          <geometry>
            <box>
              <size>0.1 0.1 0.02</size>
            </box>
          </geometry>
          <material>
            <script>
              <name>Gazebo/Red</name>
              <uri>__default__</uri>
            </script>
          </material>
        </visual>
        <self_collide>0</self_collide>
        <enable_wind>0</enable_wind>
        <kinematic>0</kinematic>
      </link>
    </model>
    <model name='irlock_beacon_01_clone_clone'>
      <pose>8.92159 7.0077 0.00743 0 0.000114 0</pose>
      <link name='link'>
        <inertial>
          <pose>0 0 0 0 -0 0</pose>
          <mass>3</mass>
          <inertia>
            <ixx>0.019</ixx>
            <ixy>0</ixy>
            <ixz>0</ixz>
            <iyy>0.01</iyy>
            <iyz>0</iyz>
            <izz>0.01</izz>
          </inertia>
        </inertial>
        <collision name='collision'>
          <geometry>
            <box>
              <size>1 1 0.02</size>
            </box>
          </geometry>
          <surface>
            <friction>
              <ode>
                <mu>1</mu>
                <mu2>1</mu2>
                <fdir1>1 0 0</fdir1>
              </ode>
              <torsional>
                <ode/>
              </torsional>
            </friction>
            <contact>
              <ode>
                <kp>1e+12</kp>
                <kd>1</kd>
                <max_vel>10</max_vel>
                <min_depth>0.003</min_depth>
              </ode>
            </contact>
            <bounce/>
          </surface>
          <max_contacts>10</max_contacts>
        </collision>
        <visual name='visual2'>
          <geometry>
            <box>
              <size>1 1 0.018</size>
            </box>
          </geometry>
          <material>
            <script>
              <name>Gazebo/Green</name>
              <uri>__default__</uri>
            </script>
          </material>
        </visual>
        <visual name='visual'>
          <geometry>
            <box>
              <size>0.1 0.1 0.02</size>
            </box>
          </geometry>
          <material>
            <script>
              <name>Gazebo/Red</name>
              <uri>__default__</uri>
            </script>
          </material>
        </visual>
        <self_collide>0</self_collide>
        <enable_wind>0</enable_wind>
        <kinematic>0</kinematic>
      </link>
    </model>
    <model name='irlock_beacon_01_clone_clone_0'>
      <pose>0.01755 7.02674 0.007414 0 0.000174 0</pose>
      <link name='link'>
        <inertial>
          <pose>0 0 0 0 -0 0</pose>
          <mass>3</mass>
          <inertia>
            <ixx>0.019</ixx>
            <ixy>0</ixy>
            <ixz>0</ixz>
            <iyy>0.01</iyy>
            <iyz>0</iyz>
            <izz>0.01</izz>
          </inertia>
        </inertial>
        <collision name='collision'>
          <geometry>
            <box>
              <size>1 1 0.02</size>
            </box>
          </geometry>
          <surface>
            <friction>
              <ode>
                <mu>1</mu>
                <mu2>1</mu2>
                <fdir1>1 0 0</fdir1>
              </ode>
              <torsional>
                <ode/>
              </torsional>
            </friction>
            <contact>
              <ode>
                <kp>1e+12</kp>
                <kd>1</kd>
                <max_vel>10</max_vel>
                <min_depth>0.003</min_depth>
              </ode>
            </contact>
            <bounce/>
          </surface>
          <max_contacts>10</max_contacts>
        </collision>
        <visual name='visual2'>
          <geometry>
            <box>
              <size>1 1 0.018</size>
            </box>
          </geometry>
          <material>
            <script>
              <name>Gazebo/Green</name>
              <uri>__default__</uri>
            </script>
          </material>
        </visual>
        <visual name='visual'>
          <geometry>
            <box>
              <size>0.1 0.1 0.02</size>
            </box>
          </geometry>
          <material>
            <script>
              <name>Gazebo/Red</name>
              <uri>__default__</uri>
            </script>
          </material>
        </visual>
        <self_collide>0</self_collide>
        <enable_wind>0</enable_wind>
        <kinematic>0</kinematic>
      </link>
    </model>
    <model name='irlock_beacon_01_clone_clone_1'>
      <pose>9.97642 -9.96773 0.007366 0 0.000355 0</pose>
      <link name='link'>
        <inertial>
          <pose>0 0 0 0 -0 0</pose>
          <mass>3</mass>
          <inertia>
            <ixx>0.019</ixx>
            <ixy>0</ixy>
            <ixz>0</ixz>
            <iyy>0.01</iyy>
            <iyz>0</iyz>
            <izz>0.01</izz>
          </inertia>
        </inertial>
        <collision name='collision'>
          <geometry>
            <box>
              <size>1 1 0.02</size>
            </box>
          </geometry>
          <surface>
            <friction>
              <ode>
                <mu>1</mu>
                <mu2>1</mu2>
                <fdir1>1 0 0</fdir1>
              </ode>
              <torsional>
                <ode/>
              </torsional>
            </friction>
            <contact>
              <ode>
                <kp>1e+12</kp>
                <kd>1</kd>
                <max_vel>10</max_vel>
                <min_depth>0.003</min_depth>
              </ode>
            </contact>
            <bounce/>
          </surface>
          <max_contacts>10</max_contacts>
        </collision>
        <visual name='visual2'>
          <geometry>
            <box>
              <size>1 1 0.018</size>
            </box>
          </geometry>
          <material>
            <script>
              <name>Gazebo/Green</name>
              <uri>__default__</uri>
            </script>
          </material>
        </visual>
        <visual name='visual'>
          <geometry>
            <box>
              <size>0.1 0.1 0.02</size>
            </box>
          </geometry>
          <material>
            <script>
              <name>Gazebo/Red</name>
              <uri>__default__</uri>
            </script>
          </material>
        </visual>
        <self_collide>0</self_collide>
        <enable_wind>0</enable_wind>
        <kinematic>0</kinematic>
      </link>
    </model>
    <model name='irlock_beacon_01_clone_0'>
      <pose>-9.89948 10.001 0.008499 -0 0.003 -0.000969</pose>
      <link name='link'>
        <inertial>
          <pose>0 0 0 0 -0 0</pose>
          <mass>3</mass>
          <inertia>
            <ixx>0.019</ixx>
            <ixy>0</ixy>
            <ixz>0</ixz>
            <iyy>0.01</iyy>
            <iyz>0</iyz>
            <izz>0.01</izz>
          </inertia>
        </inertial>
        <collision name='collision'>
          <geometry>
            <box>
              <size>1 1 0.02</size>
            </box>
          </geometry>
          <surface>
            <friction>
              <ode>
                <mu>1</mu>
                <mu2>1</mu2>
                <fdir1>1 0 0</fdir1>
              </ode>
              <torsional>
                <ode/>
              </torsional>
            </friction>
            <contact>
              <ode>
                <kp>1e+12</kp>
                <kd>1</kd>
                <max_vel>10</max_vel>
                <min_depth>0.003</min_depth>
              </ode>
            </contact>
            <bounce/>
          </surface>
          <max_contacts>10</max_contacts>
        </collision>
        <visual name='visual2'>
          <geometry>
            <box>
              <size>1 1 0.018</size>
            </box>
          </geometry>
          <material>
            <script>
              <name>Gazebo/Green</name>
              <uri>__default__</uri>
            </script>
          </material>
        </visual>
        <visual name='visual'>
          <geometry>
            <box>
              <size>0.1 0.1 0.02</size>
            </box>
          </geometry>
          <material>
            <script>
              <name>Gazebo/Red</name>
              <uri>__default__</uri>
            </script>
          </material>
        </visual>
        <self_collide>0</self_collide>
        <enable_wind>0</enable_wind>
        <kinematic>0</kinematic>
      </link>
    </model>
    <model name='irlock_beacon_01_clone_1'>
      <pose>-9.97328 -10.0375 0.008497 -1e-06 0.002995 -0.001035</pose>
      <link name='link'>
        <inertial>
          <pose>0 0 0 0 -0 0</pose>
          <mass>3</mass>
          <inertia>
            <ixx>0.019</ixx>
            <ixy>0</ixy>
            <ixz>0</ixz>
            <iyy>0.01</iyy>
            <iyz>0</iyz>
            <izz>0.01</izz>
          </inertia>
        </inertial>
        <collision name='collision'>
          <geometry>
            <box>
              <size>1 1 0.02</size>
            </box>
          </geometry>
          <surface>
            <friction>
              <ode>
                <mu>1</mu>
                <mu2>1</mu2>
                <fdir1>1 0 0</fdir1>
              </ode>
              <torsional>
                <ode/>
              </torsional>
            </friction>
            <contact>
              <ode>
                <kp>1e+12</kp>
                <kd>1</kd>
                <max_vel>10</max_vel>
                <min_depth>0.003</min_depth>
              </ode>
            </contact>
            <bounce/>
          </surface>
          <max_contacts>10</max_contacts>
        </collision>
        <visual name='visual2'>
          <geometry>
            <box>
              <size>1 1 0.018</size>
            </box>
          </geometry>
          <material>
            <script>
              <name>Gazebo/Green</name>
              <uri>__default__</uri>
            </script>
          </material>
        </visual>
        <visual name='visual'>
          <geometry>
            <box>
              <size>0.1 0.1 0.02</size>
            </box>
          </geometry>
          <material>
            <script>
              <name>Gazebo/Red</name>
              <uri>__default__</uri>
            </script>
          </material>
        </visual>
        <self_collide>0</self_collide>
        <enable_wind>0</enable_wind>
        <kinematic>0</kinematic>
      </link>
    </model>
    <model name='irlock_beacon_01_clone_2'>
      <pose>0 -10 0.008499 2e-06 0.002999 -0.001114</pose>
      <link name='link'>
        <inertial>
          <pose>0 0 0 0 -0 0</pose>
          <mass>3</mass>
          <inertia>
            <ixx>0.019</ixx>
            <ixy>0</ixy>
            <ixz>0</ixz>
            <iyy>0.01</iyy>
            <iyz>0</iyz>
            <izz>0.01</izz>
          </inertia>
        </inertial>
        <collision name='collision'>
          <geometry>
            <box>
              <size>1 1 0.02</size>
            </box>
          </geometry>
          <surface>
            <friction>
              <ode>
                <mu>1</mu>
                <mu2>1</mu2>
                <fdir1>1 0 0</fdir1>
              </ode>
              <torsional>
                <ode/>
              </torsional>
            </friction>
            <contact>
              <ode>
                <kp>1e+12</kp>
                <kd>1</kd>
                <max_vel>10</max_vel>
                <min_depth>0.003</min_depth>
              </ode>
            </contact>
            <bounce/>
          </surface>
          <max_contacts>10</max_contacts>
        </collision>
        <visual name='visual2'>
          <geometry>
            <box>
              <size>1 1 0.018</size>
            </box>
          </geometry>
          <material>
            <script>
              <name>Gazebo/Green</name>
              <uri>__default__</uri>
            </script>
          </material>
        </visual>
        <visual name='visual'>
          <geometry>
            <box>
              <size>0.1 0.1 0.02</size>
            </box>
          </geometry>
          <material>
            <script>
              <name>Gazebo/Red</name>
              <uri>__default__</uri>
            </script>
          </material>
        </visual>
        <self_collide>0</self_collide>
        <enable_wind>0</enable_wind>
        <kinematic>0</kinematic>
      </link>
    </model>
    <model name='irlock_beacon_01_clone_3'>
      <pose>-9.97328 0.037095 0.008499 -0 0.002999 -0.001186</pose>
      <link name='link'>
        <inertial>
          <pose>0 0 0 0 -0 0</pose>
          <mass>3</mass>
          <inertia>
            <ixx>0.019</ixx>
            <ixy>0</ixy>
            <ixz>0</ixz>
            <iyy>0.01</iyy>
            <iyz>0</iyz>
            <izz>0.01</izz>
          </inertia>
        </inertial>
        <collision name='collision'>
          <geometry>
            <box>
              <size>1 1 0.02</size>
            </box>
          </geometry>
          <surface>
            <friction>
              <ode>
                <mu>1</mu>
                <mu2>1</mu2>
                <fdir1>1 0 0</fdir1>
              </ode>
              <torsional>
                <ode/>
              </torsional>
            </friction>
            <contact>
              <ode>
                <kp>1e+12</kp>
                <kd>1</kd>
                <max_vel>10</max_vel>
                <min_depth>0.003</min_depth>
              </ode>
            </contact>
            <bounce/>
          </surface>
          <max_contacts>10</max_contacts>
        </collision>
        <visual name='visual2'>
          <geometry>
            <box>
              <size>1 1 0.018</size>
            </box>
          </geometry>
          <material>
            <script>
              <name>Gazebo/Green</name>
              <uri>__default__</uri>
            </script>
          </material>
        </visual>
        <visual name='visual'>
          <geometry>
            <box>
              <size>0.1 0.1 0.02</size>
            </box>
          </geometry>
          <material>
            <script>
              <name>Gazebo/Red</name>
              <uri>__default__</uri>
            </script>
          </material>
        </visual>
        <self_collide>0</self_collide>
        <enable_wind>0</enable_wind>
        <kinematic>0</kinematic>
      </link>
    </model>
  </world>
</sdf>
